<?xml version="1.0" ?>
<!-- =================================================================================== -->
<!-- |    This document was autogenerated by xacro from /home/nsrie/cnc_project_ws/src/ur5e_description/urdf/ur5e_with_new_rg2.xacro | -->
<!-- |    EDITING THIS FILE BY HAND IS NOT RECOMMENDED                                 | -->
<!-- =================================================================================== -->
<robot name="ur5e">
    <!--
    Base UR robot series xacro macro.

    NOTE: this is NOT a URDF. It cannot directly be loaded by consumers
    expecting a flattened '.urdf' file. See the top-level '.xacro' for that
    (but note: that .xacro must still be processed by the xacro command).

    For use in '.launch' files: use one of the 'load_urX.launch' convenience
    launch files.

    This file models the base kinematic chain of a UR robot, which then gets
    parameterised by various configuration files to convert it into a UR3(e),
    UR5(e), UR10(e) or UR16e.

    NOTE: the default kinematic parameters (ie: link lengths, frame locations,
    offets, etc) do not correspond to any particular robot. They are defaults
    only. There WILL be non-zero offsets between the Forward Kinematics results
    in TF (ie: robot_state_publisher) and the values reported by the Teach
    Pendant.

    For accurate (and robot-specific) transforms, the 'kinematics_parameters_file'
    parameter MUST point to a .yaml file containing the appropriate values for
    the targetted robot.

    If using the UniversalRobots/Universal_Robots_ROS_Driver, follow the steps
    described in the readme of that repository to extract the kinematic
    calibration from the controller and generate the required .yaml file.

    Main author of the migration to yaml configs: Ludovic Delval.

    Contributors to previous versions (in no particular order):

     - Felix Messmer
     - Kelsey Hawkins
     - Wim Meeussen
     - Shaun Edwards
     - Nadia Hammoudeh Garcia
     - Dave Hershberger
     - G. vd. Hoorn
     - Philip Long
     - Dave Coleman
     - Miguel Prada
     - Mathias Luedtke
     - Marcel Schnirring
     - Felix von Drigalski
     - Felix Exner
     - Jimmy Da Silva
     - Ajit Krisshna N L
     - Muhammad Asif Rana
  -->
    <!--
    NOTE: the macro defined in this file is NOT part of the public API of this
          package. Users CANNOT rely on this file being available, or stored in
          this location. Nor can they rely on the existence of the macro.
  -->
    <transmission name="shoulder_pan_trans">
        <type>transmission_interface/SimpleTransmission</type>
        <joint name="shoulder_pan_joint">
            <hardwareInterface>hardware_interface/PositionJointInterface</hardwareInterface>
        </joint>
        <actuator name="shoulder_pan_motor">
            <mechanicalReduction>1</mechanicalReduction>
            <hardwareInterface>hardware_interface/EffortJointInterface</hardwareInterface>
        </actuator>
    </transmission>
    <transmission name="shoulder_lift_trans">
        <type>transmission_interface/SimpleTransmission</type>
        <joint name="shoulder_lift_joint">
            <hardwareInterface>hardware_interface/PositionJointInterface</hardwareInterface>
        </joint>
        <actuator name="shoulder_lift_motor">
            <mechanicalReduction>1</mechanicalReduction>
            <hardwareInterface>hardware_interface/EffortJointInterface</hardwareInterface>
        </actuator>
    </transmission>
    <transmission name="elbow_trans">
        <type>transmission_interface/SimpleTransmission</type>
        <joint name="elbow_joint">
            <hardwareInterface>hardware_interface/PositionJointInterface</hardwareInterface>
        </joint>
        <actuator name="elbow_motor">
            <mechanicalReduction>1</mechanicalReduction>
            <hardwareInterface>hardware_interface/EffortJointInterface</hardwareInterface>
        </actuator>
    </transmission>
    <transmission name="wrist_1_trans">
        <type>transmission_interface/SimpleTransmission</type>
        <joint name="wrist_1_joint">
            <hardwareInterface>hardware_interface/PositionJointInterface</hardwareInterface>
        </joint>
        <actuator name="wrist_1_motor">
            <mechanicalReduction>1</mechanicalReduction>
            <hardwareInterface>hardware_interface/EffortJointInterface</hardwareInterface>
        </actuator>
    </transmission>
    <transmission name="wrist_2_trans">
        <type>transmission_interface/SimpleTransmission</type>
        <joint name="wrist_2_joint">
            <hardwareInterface>hardware_interface/PositionJointInterface</hardwareInterface>
        </joint>
        <actuator name="wrist_2_motor">
            <mechanicalReduction>1</mechanicalReduction>
            <hardwareInterface>hardware_interface/EffortJointInterface</hardwareInterface>
        </actuator>
    </transmission>
    <transmission name="wrist_3_trans">
        <type>transmission_interface/SimpleTransmission</type>
        <joint name="wrist_3_joint">
            <hardwareInterface>hardware_interface/PositionJointInterface</hardwareInterface>
        </joint>
        <actuator name="wrist_3_motor">
            <mechanicalReduction>1</mechanicalReduction>
            <hardwareInterface>hardware_interface/EffortJointInterface</hardwareInterface>
        </actuator>
    </transmission>
    <!-- The ft_sensor plugin -->
    <gazebo>
        <plugin filename="libgazebo_ros_ft_sensor.so" name="ft_sensor">
            <updateRate>100.0</updateRate>
            <topicName>ft_sensor_topic1</topicName>
            <jointName>shoulder_pan_joint</jointName>
        </plugin>
        <!-- <plugin name="gazebo_ros_control">
            <robotNamespace>/</robotNamespace>
        </plugin> -->
    </gazebo>
    <gazebo reference="shoulder_lift_joint">
        <provideFeedback>true</provideFeedback>
    </gazebo>
    <gazebo>
        <plugin filename="libgazebo_ros_ft_sensor.so" name="ft_sensor">
            <updateRate>100.0</updateRate>
            <topicName>ft_sensor_topic2</topicName>
            <jointName>shoulder_lift_joint</jointName>
        </plugin>
    </gazebo>
    <gazebo reference="elbow_joint">
        <provideFeedback>true</provideFeedback>
    </gazebo>
    <gazebo>
        <plugin filename="libgazebo_ros_ft_sensor.so" name="ft_sensor">
            <updateRate>100.0</updateRate>
            <topicName>ft_sensor_topic3</topicName>
            <jointName>elbow_joint</jointName>
        </plugin>
    </gazebo>
    <gazebo reference="wrist_1_joint">
        <provideFeedback>true</provideFeedback>
    </gazebo>
    <gazebo>
        <plugin filename="libgazebo_ros_ft_sensor.so" name="ft_sensor">
            <updateRate>100.0</updateRate>
            <topicName>ft_sensor_topic4</topicName>
            <jointName>wrist_1_joint</jointName>
        </plugin>
    </gazebo>
    <gazebo reference="wrist_2_joint">
        <provideFeedback>true</provideFeedback>
    </gazebo>
    <gazebo>
        <plugin filename="libgazebo_ros_ft_sensor.so" name="ft_sensor">
            <updateRate>100.0</updateRate>
            <topicName>ft_sensor_topic5</topicName>
            <jointName>wrist_2_joint</jointName>
        </plugin>
    </gazebo>
    <gazebo reference="wrist_3_joint">
        <provideFeedback>true</provideFeedback>
    </gazebo>
    <gazebo>
        <plugin filename="libgazebo_ros_ft_sensor.so" name="ft_sensor">
            <updateRate>100.0</updateRate>
            <topicName>ft_sensor_topic6</topicName>
            <jointName>wrist_3_joint</jointName>
        </plugin>
    </gazebo>
    <!-- links: main serial chain -->
    <link name="world" />
    <joint name="base_fixed_joint" type="fixed">
        <parent link="world" />
        <child link="base_link" />
        <origin rpy="0 0 0" xyz="0 0 0" />
    </joint>
    <link name="base_link" />
    <link name="base_link_inertia">
        <visual>
            <origin rpy="0 0 3.141592653589793" xyz="0 0 0" />
            <geometry>
                <mesh filename="package://ur5e_description/meshes/ur5e/visual/base.dae" />
            </geometry>
            <material name="LightGrey">
                <color rgba="0.7 0.7 0.7 1.0" />
            </material>
        </visual>
        <collision>
            <origin rpy="0 0 3.141592653589793" xyz="0 0 0" />
            <geometry>
                <mesh filename="package://ur5e_description/meshes/ur5e/collision/base.stl" />
            </geometry>
        </collision>
        <inertial>
            <mass value="4.0" />
            <origin rpy="0 0 0" xyz="0 0 0" />
            <inertia ixx="0.00443333156" ixy="0.0" ixz="0.0" iyy="0.00443333156" iyz="0.0" izz="0.0072" />
        </inertial>
    </link>
    <link name="shoulder_link">
        <visual>
            <origin rpy="0 0 3.141592653589793" xyz="0 0 0" />
            <geometry>
                <mesh filename="package://ur5e_description/meshes/ur5e/visual/shoulder.dae" />
            </geometry>
            <material name="LightGrey">
                <color rgba="0.7 0.7 0.7 1.0" />
            </material>
        </visual>
        <collision>
            <origin rpy="0 0 3.141592653589793" xyz="0 0 0" />
            <geometry>
                <mesh filename="package://ur5e_description/meshes/ur5e/collision/shoulder.stl" />
            </geometry>
        </collision>
        <inertial>
            <mass value="3.7" />
            <origin rpy="0 0 0" xyz="0 0 0" />
            <inertia ixx="0.010267495893" ixy="0.0" ixz="0.0" iyy="0.010267495893" iyz="0.0" izz="0.00666" />
        </inertial>
    </link>
    <link name="upper_arm_link">
        <visual>
            <origin rpy="1.5707963267948966 0 -1.5707963267948966" xyz="0 0 0.138" />
            <geometry>
                <mesh filename="package://ur5e_description/meshes/ur5e/visual/upperarm.dae" />
            </geometry>
            <material name="LightGrey">
                <color rgba="0.7 0.7 0.7 1.0" />
            </material>
        </visual>
        <collision>
            <origin rpy="1.5707963267948966 0 -1.5707963267948966" xyz="0 0 0.138" />
            <geometry>
                <mesh filename="package://ur5e_description/meshes/ur5e/collision/upperarm.stl" />
            </geometry>
        </collision>
        <inertial>
            <mass value="8.393" />
            <origin rpy="0 1.5707963267948966 0" xyz="-0.2125 0.0 0.138" />
            <inertia ixx="0.1338857818623325" ixy="0.0" ixz="0.0" iyy="0.1338857818623325" iyz="0.0" izz="0.0151074" />
        </inertial>
    </link>
    <link name="forearm_link">
        <visual>
            <origin rpy="1.5707963267948966 0 -1.5707963267948966" xyz="0 0 0.007" />
            <geometry>
                <mesh filename="package://ur5e_description/meshes/ur5e/visual/forearm.dae" />
            </geometry>
            <material name="LightGrey">
                <color rgba="0.7 0.7 0.7 1.0" />
            </material>
        </visual>
        <collision>
            <origin rpy="1.5707963267948966 0 -1.5707963267948966" xyz="0 0 0.007" />
            <geometry>
                <mesh filename="package://ur5e_description/meshes/ur5e/collision/forearm.stl" />
            </geometry>
        </collision>
        <inertial>
            <mass value="2.275" />
            <origin rpy="0 1.5707963267948966 0" xyz="-0.1961 0.0 0.007" />
            <inertia ixx="0.031209355099586295" ixy="0.0" ixz="0.0" iyy="0.031209355099586295" iyz="0.0" izz="0.004095" />
        </inertial>
    </link>
    <link name="wrist_1_link">
        <visual>
            <!-- TODO: Move this to a parameter -->
            <origin rpy="1.5707963267948966 0 0" xyz="0 0 -0.127" />
            <geometry>
                <mesh filename="package://ur5e_description/meshes/ur5e/visual/wrist1.dae" />
            </geometry>
            <material name="LightGrey">
                <color rgba="0.7 0.7 0.7 1.0" />
            </material>
        </visual>
        <collision>
            <origin rpy="1.5707963267948966 0 0" xyz="0 0 -0.127" />
            <geometry>
                <mesh filename="package://ur5e_description/meshes/ur5e/collision/wrist1.stl" />
            </geometry>
        </collision>
        <inertial>
            <mass value="1.219" />
            <origin rpy="0 0 0" xyz="0 0 0" />
            <inertia ixx="0.0025598989760400002" ixy="0.0" ixz="0.0" iyy="0.0025598989760400002" iyz="0.0" izz="0.0021942" />
        </inertial>
    </link>
    <link name="wrist_2_link">
        <visual>
            <origin rpy="0 0 0" xyz="0 0 -0.0997" />
            <geometry>
                <mesh filename="package://ur5e_description/meshes/ur5e/visual/wrist2.dae" />
            </geometry>
            <material name="LightGrey">
                <color rgba="0.7 0.7 0.7 1.0" />
            </material>
        </visual>
        <collision>
            <origin rpy="0 0 0" xyz="0 0 -0.0997" />
            <geometry>
                <mesh filename="package://ur5e_description/meshes/ur5e/collision/wrist2.stl" />
            </geometry>
        </collision>
        <inertial>
            <mass value="1.219" />
            <origin rpy="0 0 0" xyz="0 0 0" />
            <inertia ixx="0.0025598989760400002" ixy="0.0" ixz="0.0" iyy="0.0025598989760400002" iyz="0.0" izz="0.0021942" />
        </inertial>
    </link>
    <link name="wrist_3_link">
        <visual>
            <origin rpy="1.5707963267948966 0 0" xyz="0 0 -0.0989" />
            <geometry>
                <mesh filename="package://ur5e_description/meshes/ur5e/visual/wrist3.dae" />
            </geometry>
            <material name="LightGrey">
                <color rgba="0.7 0.7 0.7 1.0" />
            </material>
        </visual>
        <collision>
            <origin rpy="1.5707963267948966 0 0" xyz="0 0 -0.0989" />
            <geometry>
                <mesh filename="package://ur5e_description/meshes/ur5e/collision/wrist3.stl" />
            </geometry>
        </collision>
        <inertial>
            <mass value="0.1879" />
            <origin rpy="0 0 0" xyz="0.0 0.0 -0.0229" />
            <inertia ixx="9.890410052167731e-05" ixy="0.0" ixz="0.0" iyy="9.890410052167731e-05" iyz="0.0" izz="0.0001321171875" />
        </inertial>
    </link>
    <!-- joints: main serial chain -->
    <joint name="base_link-base_link_inertia" type="fixed">
        <parent link="base_link" />
        <child link="base_link_inertia" />
        <!-- 'base_link' is REP-103 aligned (so X+ forward), while the internal
           frames of the robot/controller have X+ pointing backwards.
           Use the joint between 'base_link' and 'base_link_inertia' (a dummy
           link/frame) to introduce the necessary rotation over Z (of pi rad).
      -->
        <origin rpy="0 0 3.141592653589793" xyz="0 0 0" />
    </joint>
    <joint name="shoulder_pan_joint" type="revolute">
        <parent link="base_link_inertia" />
        <child link="shoulder_link" />
        <origin rpy="0 0 1.969933668384549e-05" xyz="0 0 0.1626295756380534" />
        <axis xyz="0 0 1" />
        <limit effort="150.0" lower="-6.283185307179586" upper="6.283185307179586" velocity="3.141592653589793" />
        <dynamics damping="0" friction="0" />
    </joint>
    <joint name="shoulder_lift_joint" type="revolute">
        <parent link="shoulder_link" />
        <child link="upper_arm_link" />
        <origin rpy="1.570016073431258 0 3.124381442188215e-05" xyz="-3.413074790722222e-05 0 0" />
        <axis xyz="0 0 1" />
        <limit effort="150.0" lower="-6.283185307179586" upper="6.283185307179586" velocity="3.141592653589793" />
        <dynamics damping="0" friction="0" />
    </joint>
    <joint name="elbow_joint" type="revolute">
        <parent link="upper_arm_link" />
        <child link="forearm_link" />
        <origin rpy="3.141327912955879 3.141040704748785 -3.104252082289484" xyz="-0.4252509561184845 0 0" />
        <axis xyz="0 0 1" />
        <limit effort="150.0" lower="-3.141592653589793" upper="3.141592653589793" velocity="3.141592653589793" />
        <dynamics damping="0" friction="0" />
    </joint>
    <joint name="wrist_1_joint" type="revolute">
        <parent link="forearm_link" />
        <child link="wrist_1_link" />
        <origin rpy="0.003757710702399783 -0.0003572380041479283 0.003569648385756133" xyz="-0.3922685290596098 -0.0005014244478493389 0.133438182834038" />
        <axis xyz="0 0 1" />
        <limit effort="28.0" lower="-6.283185307179586" upper="6.283185307179586" velocity="3.141592653589793" />
        <dynamics damping="0" friction="0" />
    </joint>
    <joint name="wrist_2_joint" type="revolute">
        <parent link="wrist_1_link" />
        <child link="wrist_2_link" />
        <origin rpy="1.570874482694964 0 4.485408697310623e-07" xyz="0.0001431503502017681 -0.09966611014412317 -7.789494560421327e-06" />
        <axis xyz="0 0 1" />
        <limit effort="28.0" lower="-6.283185307179586" upper="6.283185307179586" velocity="3.141592653589793" />
        <dynamics damping="0" friction="0" />
    </joint>
    <joint name="wrist_3_joint" type="revolute">
        <parent link="wrist_2_link" />
        <child link="wrist_3_link" />
        <origin rpy="1.570643318053783 3.141592653589793 -3.141592393635845" xyz="3.082536844710822e-05 0.09956099523210188 -1.523370266336512e-05" />
        <axis xyz="0 0 1" />
        <limit effort="28.0" lower="-6.283185307179586" upper="6.283185307179586" velocity="3.141592653589793" />
        <dynamics damping="0" friction="0" />
    </joint>
    <!-- ROS-Industrial 'base' frame: base_link to UR 'Base' Coordinates transform -->
    <link name="base" />
    <joint name="base_link-base_fixed_joint" type="fixed">
        <!-- Note the rotation over Z of pi radians: as base_link is REP-103
           aligned (ie: has X+ forward, Y+ left and Z+ up), this is needed
           to correctly align 'base' with the 'Base' coordinate system of
           the UR controller.
      -->
        <origin rpy="0 0 3.141592653589793" xyz="0 0 0" />
        <parent link="base_link" />
        <child link="base" />
    </joint>
    <!-- ROS-Industrial 'flange' frame: attachment point for EEF models -->
    <link name="flange" />
    <joint name="wrist_3-flange" type="fixed">
        <parent link="wrist_3_link" />
        <child link="flange" />
        <origin rpy="0 -1.5707963267948966 -1.5707963267948966" xyz="0 0 0" />
    </joint>
    <!-- ROS-Industrial 'tool0' frame: all-zeros tool frame -->
    <link name="tool0" />
    <joint name="flange-tool0" type="fixed">
        <!-- default toolframe: X+ left, Y+ up, Z+ front -->
        <origin rpy="1.5707963267948966 0 1.5707963267948966" xyz="0 0 0" />
        <parent link="flange" />
        <child link="tool0" />
    </joint>
    <!-- ros_control plugin -->
    <gazebo>
        <plugin filename="libgazebo_ros_control.so" name="gazebo_ros_control">
            <robotNamespace>/UR5e</robotNamespace>
        </plugin>
    </gazebo>
    <!-- Hand -->
    <gazebo reference="hand_link">
        <mu1>0.2</mu1>
        <mu2>0.2</mu2>
        <material>Gazebo/White</material>
        <selfCollide>false</selfCollide>
    </gazebo>
    <!-- Left Finger -->
    <gazebo reference="l_moment_arm_link">
        <mu1>0.2</mu1>
        <mu2>0.2</mu2>
        <material>Gazebo/White</material>
        <selfCollide>false</selfCollide>
    </gazebo>
    <gazebo reference="l_truss_arm_link">
        <mu1>0.2</mu1>
        <mu2>0.2</mu2>
        <material>Gazebo/White</material>
        <selfCollide>false</selfCollide>
    </gazebo>
    <gazebo reference="l_finger">
        <mu1>0.2</mu1>
        <mu2>0.2</mu2>
        <material>Gazebo/White</material>
        <selfCollide>false</selfCollide>
    </gazebo>
    <!-- Right Finger -->
    <gazebo reference="r_moment_arm_link">
        <mu1>0.2</mu1>
        <mu2>0.2</mu2>
        <material>Gazebo/White</material>
        <selfCollide>false</selfCollide>
    </gazebo>
    <gazebo reference="r_truss_arm_link">
        <mu1>0.2</mu1>
        <mu2>0.2</mu2>
        <material>Gazebo/White</material>
        <selfCollide>false</selfCollide>
    </gazebo>
    <gazebo reference="r_finger">
        <mu1>0.2</mu1>
        <mu2>0.2</mu2>
        <material>Gazebo/White</material>
        <selfCollide>false</selfCollide>
    </gazebo>
    <link name="hand_link">
        <collision>
            <origin rpy="0.00 0.00 0.00" xyz="0.00 0.00 0.00" />
            <geometry>
                <mesh filename="package://new_rg2_description/meshes/collision/RG2_Hand_col.STL" />
            </geometry>
        </collision>
        <visual>
            <origin rpy="0.00 0.00 0.00" xyz="0.00 0.00 0.00" />
            <geometry>
                <mesh filename="package://new_rg2_description/meshes/visual/RG2_Hand_vis.STL" />
                <material name="white">
                    <color rgba="0.7058823529411765 0.7058823529411765 0.7058823529411765 1.0" />
                </material>
            </geometry>
        </visual>
        <!-- <inertial>
            <origin xyz="0.058091 0.000192 -0.000016" rpy="0.00 0.00 0.00"/>
            <mass value="0.524520"/>
            <inertia ixx="0.000193" ixy="0.000000" ixz="0.000000"
                     iyy="0.000564" iyz="-0.000001"
                     izz="0.000636" />
        </inertial> -->
        <inertial>
            <origin rpy="0.00 0.00 0.00" xyz="0.061902 0.000129 -0.000005" />
            <mass value="1.684558" />
            <inertia ixx="0.000862" ixy="0.000000" ixz="0.000000" iyy="0.002401" iyz="-0.000001" izz="0.002620" />
        </inertial>
    </link>
    <!-- Jari Kiri -->
    <joint name="gripper_joint" type="revolute">
        <parent link="hand_link" />
        <child link="l_moment_arm_link" />
        <origin rpy="0 0 0" xyz="0.105 0.017 0.010" />
        <axis xyz="0 0 1" />
        <limit effort="10.6" lower="-0.45" upper="1.570796327" velocity="3.14" />
        <!-- <limit velocity="3.14" effort="100" lower="-3" upper="3" /> -->
        <dynamics damping="0.1" friction="0.0" />
        <implicitSpringDamper>True</implicitSpringDamper>
    </joint>
    <transmission name="gripper_joint_tran">
        <type>transmission_interface/SimpleTransmission</type>
        <joint name="gripper_joint">
            <hardwareInterface>hardware_interface/EffortJointInterface</hardwareInterface>
        </joint>
        <actuator name="gripper_joint_motor">
           <hardwareInterface>hardware_interface/EffortJointInterface</hardwareInterface>
            <mechanicalReduction>1</mechanicalReduction>
        </actuator>
    </transmission>
    <link name="l_moment_arm_link">
        <collision>
            <origin rpy="0.00 0.00 0.00" xyz="0.00 0.00 0.00" />
            <geometry>
                <mesh filename="package://new_rg2_description/meshes/collision/RG2_LeftMomentArm_col.STL" />
            </geometry>
        </collision>
        <visual>
            <origin rpy="0.00 0.00 0.00" xyz="0.00 0.00 0.00" />
            <geometry>
                <mesh filename="package://new_rg2_description/meshes/visual/RG2_LeftMomentArm_vis.STL" />
                <material name="gray1">
                    <color rgba="0.47058823529411764 0.47058823529411764 0.47058823529411764 1.0" />
                </material>
            </geometry>
        </visual>
        <inertial>
            <origin rpy="0.00 0.00 0.00" xyz="0.017004 0.006397 -0.010300" />
            <mass value="0.160209" />
            <inertia ixx="0.000023" ixy="0.000019" ixz="0.000000" iyy="0.000072" iyz="0.000000" izz="0.000083" />
        </inertial>
    </link>
    <joint name="l_finger_2_joint" type="revolute">
        <parent link="l_moment_arm_link" />
        <child link="l_finger_link" />
        <origin rpy="0 0 0" xyz="0.049 0.026 0.000" />
        <axis xyz="0 0 1" />
        <limit effort="10.6" lower="-1.570796327" upper="1.570796327" velocity="3.14" />
        <!-- <limit velocity="3.14" effort="100" lower="-3" upper="3" /> -->
        <mimic joint="gripper_joint" multiplier="-1" />
        <dynamics damping="0.1" friction="0.0" />
        <implicitSpringDamper>True</implicitSpringDamper>
    </joint>
    <gazebo>
        <plugin filename="libroboticsgroup_gazebo_mimic_joint_plugin.so" name="l_finger_2_jointmimic_joint_plugin">
            <joint>gripper_joint</joint>
            <mimicJoint>l_finger_2_joint</mimicJoint>
            <multiplier>-1.0</multiplier>
            <offset>0</offset>
            
            <sensitiveness>0.0</sensitiveness>
            <!-- if absolute difference between setpoint and process value is below this threshold, do nothing; 0.0 = disable [rad] -->
            <maxEffort>10.6</maxEffort>
        </plugin>
    </gazebo>
    <link name="l_finger_link">
        <collision>
            <origin rpy="0.00 0.00 0.00" xyz="0.00 0.00 0.00" />
            <geometry>
                <mesh filename="package://new_rg2_description/meshes/collision/RG2_LeftFinger_col.STL" />
            </geometry>
        </collision>
        <visual>
            <origin rpy="0.00 0.00 0.00" xyz="0.00 0.00 0.00" />
            <geometry>
                <mesh filename="package://new_rg2_description/meshes/visual/RG2_LeftFinger_vis.STL" />
                <material name="dark_gray">
                    <color rgba="0.27450980392156865 0.27450980392156865 0.27450980392156865 1.0" />
                </material>
            </geometry>
        </visual>
        <inertial>
            <origin rpy="0.00 0.00 0.00" xyz="0.024695 -0.010178 -0.010001" />
            <mass value="0.081638" />
            <inertia ixx="0.000006" ixy="-0.000005" ixz="0.000000" iyy="0.000025" iyz="0.000000" izz="0.000026" />
        </inertial>
    </link>
    <joint name="l_finger_passive_joint" type="revolute">
        <parent link="hand_link" />
        <child link="l_truss_arm_link" />
        <origin rpy="0 0 0" xyz="0.122 0.008 0.010" />
        <axis xyz="0 0 1" />
        <limit effort="10.6" lower="-1.570796327" upper="1.570796327" velocity="3.14" />
        <!-- <limit velocity="3.14" effort="100" lower="-3" upper="3" /> -->
        <mimic joint="gripper_joint" multiplier="1" />
        <dynamics damping="0.1" friction="0.0" />
        <implicitSpringDamper>True</implicitSpringDamper>
    </joint>
    <gazebo>
        <plugin filename="libroboticsgroup_gazebo_mimic_joint_plugin.so" name="l_finger_passive_jointmimic_joint_plugin">
            <joint>gripper_joint</joint>
            <mimicJoint>l_finger_passive_joint</mimicJoint>
            <multiplier>1.0</multiplier>
            <offset>0</offset>
            
            <sensitiveness>0.0</sensitiveness>
            <!-- if absolute difference between setpoint and process value is below this threshold, do nothing; 0.0 = disable [rad] -->
            <maxEffort>10.6</maxEffort>
        </plugin>
    </gazebo>
    <link name="l_truss_arm_link">
        <collision>
            <origin rpy="0.00 0.00 0.00" xyz="0.00 0.00 0.00" />
            <geometry>
                <mesh filename="package://new_rg2_description/meshes/collision/RG2_LeftTrussArm_col.STL" />
            </geometry>
        </collision>
        <visual>
            <origin rpy="0.00 0.00 0.00" xyz="0.00 0.00 0.00" />
            <geometry>
                <mesh filename="package://new_rg2_description/meshes/visual/RG2_LeftTrussArm_vis.STL" />
                <material name="gray1">
                    <color rgba="0.47058823529411764 0.47058823529411764 0.47058823529411764 1.0" />
                </material>
            </geometry>
        </visual>
        <inertial>
            <origin rpy="0.00 0.00 0.00" xyz="0.023075 0.012136 -0.010000" />
            <mass value="0.065927" />
            <inertia ixx="0.000010" ixy="0.000010" ixz="0.000000" iyy="0.000024" iyz="0.000000" izz="0.000025" />
        </inertial>
    </link>
    <!-- Jari Kanan -->
    <joint name="r_finger_1_joint" type="revolute">
        <parent link="hand_link" />
        <child link="r_moment_arm_link" />
        <origin rpy="0 0 0" xyz="0.105 -0.017 0.010" />
        <axis xyz="0 0 1" />
        <limit effort="10.6" lower="-1.570796327" upper="1.570796327" velocity="3.14" />
        <!-- <limit velocity="3.14" effort="100" lower="-3" upper="3" /> -->
        <mimic joint="gripper_joint" multiplier="-1" />
        <dynamics damping="0.1" friction="0.0" />
        <implicitSpringDamper>True</implicitSpringDamper>
    </joint>
    <gazebo>
        <plugin filename="libroboticsgroup_gazebo_mimic_joint_plugin.so" name="r_finger_1_jointmimic_joint_plugin">
            <joint>gripper_joint</joint>
            
            <mimicJoint>r_finger_1_joint</mimicJoint>
            <multiplier>-1.0</multiplier>
            <offset>0</offset>
            <sensitiveness>0.0</sensitiveness>
            <!-- if absolute difference between setpoint and process value is below this threshold, do nothing; 0.0 = disable [rad] -->
            <maxEffort>10.6</maxEffort>
        </plugin>
    </gazebo>
    <link name="r_moment_arm_link">
        <collision>
            <origin rpy="0.00 0.00 0.00" xyz="0.00 0.00 0.00" />
            <geometry>
                <mesh filename="package://new_rg2_description/meshes/collision/RG2_RightMomentArm_col.STL" />
            </geometry>
        </collision>
        <visual>
            <origin rpy="0.00 0.00 0.00" xyz="0.00 0.00 0.00" />
            <geometry>
                <mesh filename="package://new_rg2_description/meshes/visual/RG2_RightMomentArm_vis.STL" />
                <material name="gray1">
                    <color rgba="0.47058823529411764 0.47058823529411764 0.47058823529411764 1.0" />
                </material>
            </geometry>
        </visual>
        <inertial>
            <origin rpy="0.00 0.00 0.00" xyz="0.017004 -0.006397 -0.010300" />
            <mass value="0.160209" />
            <inertia ixx="0.000023" ixy="-0.000019" ixz="0.000000" iyy="0.000072" iyz="0.000000" izz="0.000083" />
        </inertial>
    </link>
    <joint name="r_finger_2_joint" type="revolute">
        <parent link="r_moment_arm_link" />
        <child link="r_finger_link" />
        <origin rpy="0 0 0" xyz="0.049 -0.026 0.000" />
        <axis xyz="0 0 1" />
        <limit effort="10.6" lower="-1.570796327" upper="1.570796327" velocity="3.14" />
        <!-- <limit velocity="3.14" effort="100" lower="-3" upper="3" /> -->
        <mimic joint="gripper_joint" multiplier="1" />
        <dynamics damping="0.1" friction="0.0" />
        <implicitSpringDamper>True</implicitSpringDamper>
    </joint>
    <gazebo>
        <plugin filename="libroboticsgroup_gazebo_mimic_joint_plugin.so" name="r_finger_2_jointmimic_joint_plugin">
            <joint>gripper_joint</joint>
            
            <mimicJoint>r_finger_2_joint</mimicJoint>
            <multiplier>1.0</multiplier>
            <offset>0</offset>
            <sensitiveness>0.0</sensitiveness>
            <!-- if absolute difference between setpoint and process value is below this threshold, do nothing; 0.0 = disable [rad] -->
            <maxEffort>10.6</maxEffort>
        </plugin>
    </gazebo>
    <link name="r_finger_link">
        <collision>
            <origin rpy="0.00 0.00 0.00" xyz="0.00 0.00 0.00" />
            <geometry>
                <mesh filename="package://new_rg2_description/meshes/collision/RG2_RightFinger_col.STL" />
            </geometry>
        </collision>
        <visual>
            <origin rpy="0.00 0.00 0.00" xyz="0.00 0.00 0.00" />
            <geometry>
                <mesh filename="package://new_rg2_description/meshes/visual/RG2_RightFinger_vis.STL" />
                <material name="dark_gray">
                    <color rgba="0.27450980392156865 0.27450980392156865 0.27450980392156865 1.0" />
                </material>
            </geometry>
        </visual>
        <inertial>
            <origin rpy="0.00 0.00 0.00" xyz="0.024695 0.010178 -0.010000" />
            <mass value="0.081637" />
            <inertia ixx="0.000006" ixy="0.000005" ixz="0.000000" iyy="0.000025" iyz="0.000000" izz="0.000026" />
        </inertial>
    </link>
    <joint name="r_finger_passive_joint" type="revolute">
        <parent link="hand_link" />
        <child link="r_truss_arm_link" />
        <origin rpy="0 0 0" xyz="0.122 -0.008 0.010" />
        <axis xyz="0 0 1" />
        <limit effort="10.6" lower="-1.570796327" upper="1.570796327" velocity="3.14" />
        <!-- <limit velocity="3.14" effort="100" lower="-3" upper="3" /> -->
        <mimic joint="gripper_joint" multiplier="-1" />
        <dynamics damping="0.1" friction="0.0" />
        <implicitSpringDamper>True</implicitSpringDamper>
    </joint>
    <gazebo>
        <plugin filename="libroboticsgroup_gazebo_mimic_joint_plugin.so" name="r_finger_passive_jointmimic_joint_plugin">
            <joint>gripper_joint</joint>
            
            <mimicJoint>r_finger_passive_joint</mimicJoint>
            <multiplier>-1.0</multiplier>
            <offset>0</offset>
            <sensitiveness>0.0</sensitiveness>
            <!-- if absolute difference between setpoint and process value is below this threshold, do nothing; 0.0 = disable [rad] -->
            <maxEffort>10.6</maxEffort>
        </plugin>
    </gazebo>
    <link name="r_truss_arm_link">
        <collision>
            <origin rpy="0.00 0.00 0.00" xyz="0.00 0.00 0.00" />
            <geometry>
                <mesh filename="package://new_rg2_description/meshes/collision/RG2_RightTrussArm_col.STL" />
            </geometry>
        </collision>
        <visual>
            <origin rpy="0.00 0.00 0.00" xyz="0.00 0.00 0.00" />
            <geometry>
                <mesh filename="package://new_rg2_description/meshes/visual/RG2_RightTrussArm_vis.STL" />
                <material name="gray1">
                    <color rgba="0.47058823529411764 0.47058823529411764 0.47058823529411764 1.0" />
                </material>
            </geometry>
        </visual>
        <inertial>
            <origin rpy="0.00 0.00 0.00" xyz="0.023075 -0.012136 -0.010000" />
            <mass value="0.065927" />
            <inertia ixx="0.000010" ixy="-0.000010" ixz="0.000000" iyy="0.000024" iyz="0.000000" izz="0.000025" />
        </inertial>
    </link>
    <joint name="hand_joint" type="fixed">
        <origin rpy="1.57 -1.57 0" xyz="0 0 0" />
        <parent link="tool0" />
        <child link="hand_link" />
    </joint>
    <gazebo>
        <plugin filename="libgazebo_ros_control.so" name="gazebo_ros_control" />
    </gazebo>
    <!-- <transmission name="trans_l_finger_2_joint">
        <type>transmission_interface/SimpleTransmission</type>
        <joint name="l_finger_2_joint">
            <hardwareInterface>hardware_interface/PositionJointInterface</hardwareInterface>
        </joint>
        <actuator name="l_finger_2_joint_motor">
            <hardwareInterface>hardware_interface/EffortJointInterface</hardwareInterface>
            <mechanicalReduction>1</mechanicalReduction>
        </actuator>
    </transmission> -->
    <!-- <transmission name="trans_l_finger_passive_joint">
        <type>transmission_interface/SimpleTransmission</type>
        <joint name="l_finger_passive_joint">
            <hardwareInterface>hardware_interface/PositionJointInterface</hardwareInterface>
        </joint>
        <actuator name="l_finger_passive_joint_motor">
            <hardwareInterface>hardware_interface/PositionJointInterface</hardwareInterface>
            <mechanicalReduction>1</mechanicalReduction>
        </actuator>
    </transmission> -->
    <!-- <transmission name="trans_r_finger_1_joint">
        <type>transmission_interface/SimpleTransmission</type>
        <joint name="r_finger_1_joint">
            <hardwareInterface>hardware_interface/PositionJointInterface</hardwareInterface>
        </joint>
        <actuator name="r_finger_1_joint_motor">
            <hardwareInterface>hardware_interface/EffortJointInterface</hardwareInterface>
            <mechanicalReduction>1</mechanicalReduction>
        </actuator>
    </transmission> -->
    <!-- <transmission name="trans_r_finger_2_joint">
        <type>transmission_interface/SimpleTransmission</type>
        <joint name="r_finger_2_joint">
            <hardwareInterface>hardware_interface/PositionJointInterface</hardwareInterface>
        </joint>
        <actuator name="r_finger_2_joint_motor">
            <hardwareInterface>hardware_interface/EffortJointInterface</hardwareInterface>
            <mechanicalReduction>1</mechanicalReduction>
        </actuator>
    </transmission> -->
    <!-- <transmission name="trans_r_finger_passive_joint">
        <type>transmission_interface/SimpleTransmission</type>
        <joint name="r_finger_passive_joint">
            <hardwareInterface>hardware_interface/EffortJointInterface</hardwareInterface>
        </joint>
        <actuator name="r_finger_passive_joint_motor">
            <hardwareInterface>hardware_interface/EffortJointInterface</hardwareInterface>
            <mechanicalReduction>1</mechanicalReduction>
        </actuator>
    </transmission> -->
</robot>

